#VRML_SIM R2023b utf8

EXTERNPROTO "https://raw.githubusercontent.com/cyberbotics/webots/R2023b/projects/objects/backgrounds/protos/TexturedBackground.proto"
EXTERNPROTO "https://raw.githubusercontent.com/cyberbotics/webots/R2023b/projects/objects/backgrounds/protos/TexturedBackgroundLight.proto"
EXTERNPROTO "https://raw.githubusercontent.com/cyberbotics/webots/R2023b/projects/objects/floors/protos/RectangleArena.proto"
EXTERNPROTO "https://raw.githubusercontent.com/cyberbotics/webots/R2023b/projects/appearances/protos/BrushedAluminium.proto"
EXTERNPROTO "https://raw.githubusercontent.com/cyberbotics/webots/R2023b/projects/appearances/protos/CementTiles.proto"
EXTERNPROTO "https://raw.githubusercontent.com/cyberbotics/webots/R2023b/projects/appearances/protos/BakelitePlastic.proto"
EXTERNPROTO "https://raw.githubusercontent.com/cyberbotics/webots/R2023b/projects/objects/floors/protos/CircleArena.proto"
EXTERNPROTO "https://raw.githubusercontent.com/cyberbotics/webots/R2023b/projects/appearances/protos/Parquetry.proto"
EXTERNPROTO "https://raw.githubusercontent.com/cyberbotics/webots/R2023b/projects/objects/toys/protos/RubberDuck.proto"

WorldInfo {
}
Viewpoint {
  orientation -0.22823051225553959 -0.2402793729809883 0.9434917361564102 4.814961927979113
  position -2.6233077193888255 14.443015451570107 6.19849957797821
}
TexturedBackground {
}
TexturedBackgroundLight {
}
RectangleArena {
  floorSize 10 10
  floorTileSize 1 1
  floorAppearance Parquetry {
    type "dark strip"
    colorOverride 0 1 0
    IBLStrength 10
  }
  wallThickness 0.1
  wallHeight 0.5
}
Robot {
  translation 0 0 0.4
  children [
    Solid {
      translation 0 0 0.2
      children [
        HingeJoint {
          jointParameters HingeJointParameters {
            position 1.57
            axis 0 1 0
            anchor 0 0 0.05
          }
          device [
            RotationalMotor {
              name "camera motor"
              maxPosition 1.75
            }
          ]
          endPoint Solid {
            translation 0.09998747870966607 -6.170639877511876e-06 0.049951635625651754
            rotation 8.061402666508011e-06 0.9999999997400977 -2.1326473543421014e-05 1.5700000003756482
            children [
              Camera {
                translation -7.13725e-07 0 0.16
                rotation 0 1 0 -1.5707953071795862
              }
              DEF CameraMount Shape {
                appearance BakelitePlastic {
                }
                geometry Box {
                  size 0.05 0.1 0.3
                }
              }
            ]
            boundingObject USE CameraMount
            physics Physics {
            }
          }
        }
        Shape {
          appearance BakelitePlastic {
          }
          geometry Box {
            size 0.05 0.1 0.1
          }
        }
      ]
      name "Camera Joint"
      boundingObject Box {
        size 0.05 0.1 0.025
      }
      physics Physics {
      }
    }
    TouchSensor {
      translation 0.25 0.1 0
      rotation 0 0 1 0.261799
      children [
        DEF TouchSensor Shape {
          appearance CementTiles {
          }
          geometry Box {
            size 0.05 0.15 0.15
          }
        }
      ]
      name "left sensor"
      boundingObject USE TouchSensor
    }
    TouchSensor {
      translation 0.25 -0.1 0
      rotation 0 0 1 -0.261799
      children [
        DEF TouchSensor Shape {
          appearance CementTiles {
          }
          geometry Box {
            size 0.05 0.15 0.15
          }
        }
      ]
      name "right sensor"
      boundingObject USE TouchSensor
    }
    Track {
      translation 0 0.3 -0.125
      children [
        TrackWheel {
          position 0.175 0
          rotation 0.1978196262859132 0.6931319737121838 -0.6931345197535282 2.75099771150796
          children [
            Shape {
              geometry Box {
                size 0.1 0.1 0.1
              }
            }
            DEF Sandwhich_Wheel Shape {
              appearance PBRAppearance {
              }
              geometry Cylinder {
                height 0.05
                radius 0.1
              }
            }
          ]
        }
        TrackWheel {
          position -0.175 0
          rotation 0.1978196262859132 0.6931319737121838 -0.6931345197535282 2.75099771150796
          children [
            Shape {
              geometry Box {
                size 0.1 0.1 0.1
              }
            }
            DEF Sandwhich_Wheel Shape {
              appearance PBRAppearance {
              }
              geometry Cylinder {
                height 0.05
                radius 0.1
              }
            }
          ]
        }
      ]
      name "track1"
      boundingObject Group {
        children [
          Pose {
            translation 0.175 0 0
            rotation 1 0 0 1.5708
            children [
              Cylinder {
                height 0.1
                radius 0.1
              }
            ]
          }
          Pose {
            translation -0.175 0 0
            rotation 1 0 0 1.5708
            children [
              Cylinder {
                height 0.1
                radius 0.1
              }
            ]
          }
          DEF Track_Box_Shape Box {
            size 0.35 0.1 0.2
          }
        ]
      }
      physics Physics {
      }
      device [
        LinearMotor {
          name "leftMotor"
        }
      ]
      animatedGeometry Shape {
        appearance Appearance {
          material Material {
            diffuseColor 0 0 0
          }
        }
        geometry DEF Track_Box_Shape Box {
          size 0.05 0.1 0.01
        }
      }
      geometriesCount 25
    }
    Track {
      translation 0 -0.3 -0.125
      children [
        TrackWheel {
          position 0.175 0
          rotation 0.23583007321750035 0.6871610828773356 -0.687163606970768 2.6783974022353587
          children [
            Shape {
              geometry Box {
                size 0.1 0.1 0.1
              }
            }
            DEF Sandwhich_Wheel Shape {
              appearance PBRAppearance {
              }
              geometry Cylinder {
                height 0.05
                radius 0.1
              }
            }
          ]
        }
        TrackWheel {
          position -0.175 0
          rotation 0.23583007321750035 0.6871610828773356 -0.687163606970768 2.6783974022353587
          children [
            Shape {
              geometry Box {
                size 0.1 0.1 0.1
              }
            }
            DEF Sandwhich_Wheel Shape {
              appearance PBRAppearance {
              }
              geometry Cylinder {
                height 0.05
                radius 0.1
              }
            }
          ]
        }
      ]
      name "track2"
      boundingObject Group {
        children [
          Pose {
            translation 0.175 0 0
            rotation 1 0 0 1.5708
            children [
              Cylinder {
                height 0.1
                radius 0.1
              }
            ]
          }
          Pose {
            translation -0.175 0 0
            rotation 1 0 0 1.5708
            children [
              Cylinder {
                height 0.1
                radius 0.1
              }
            ]
          }
          DEF Track_Box_Shape Box {
            size 0.35 0.1 0.2
          }
        ]
      }
      physics Physics {
      }
      device [
        LinearMotor {
          name "rightMotor"
        }
      ]
      animatedGeometry Shape {
        appearance Appearance {
          material Material {
            diffuseColor 0 0 0
          }
        }
        geometry DEF Track_Box_Shape Box {
          size 0.05 0.1 0.01
        }
      }
      geometriesCount 25
    }
    DEF Plate Shape {
      appearance BrushedAluminium {
        colorOverride 1 0.5 0.4
      }
      geometry Box {
        size 0.5 0.5 0.35
      }
    }
  ]
  boundingObject USE Plate
  physics Physics {
  }
  controller "BasicController"
}
CircleArena {
  translation 0 0 0.1
  radius 2.5
  floorAppearance Parquetry {
    type "dark strip"
    IBLStrength 1000
  }
  floorTileSize 1 1
  wallThickness 0.05
  wallHeight 0.01
  wallAppearance BrushedAluminium {
    colorOverride 0 0 0
  }
}
RubberDuck {
  translation 0 3.04 0.24
  scale 4
  bodyColor 0.137255 0.439216 1
}
Solid {
  translation 0 3.76 0.3
  children [
    Shape {
      appearance Appearance {
        material Material {
          diffuseColor 0.717647 0.188235 0.0941176
          specularColor 1 1 1
        }
      }
      geometry Box {
        size 0.35 0.35 0.35
      }
    }
  ]
  name "Box"
  boundingObject Box {
    size 0.35 0.35 0.35
  }
  physics Physics {
  }
}
Solid {
  translation 0 4.41 0.3
  children [
    Shape {
      appearance Appearance {
        material Material {
          diffuseColor 0.172549 0.34902 0.521569
          specularColor 1 1 1
        }
      }
      geometry Sphere {
        radius 0.175
      }
    }
  ]
  name "Ball"
  boundingObject Sphere {
    radius 0.175
  }
  physics Physics {
  }
}
