#VRML_SIM R2023b utf8

EXTERNPROTO "https://raw.githubusercontent.com/cyberbotics/webots/R2023b/projects/objects/backgrounds/protos/TexturedBackground.proto"
EXTERNPROTO "https://raw.githubusercontent.com/cyberbotics/webots/R2023b/projects/objects/backgrounds/protos/TexturedBackgroundLight.proto"
EXTERNPROTO "https://raw.githubusercontent.com/cyberbotics/webots/R2023b/projects/objects/floors/protos/RectangleArena.proto"
EXTERNPROTO "https://raw.githubusercontent.com/cyberbotics/webots/R2023b/projects/appearances/protos/BrushedAluminium.proto"
EXTERNPROTO "https://raw.githubusercontent.com/cyberbotics/webots/R2023b/projects/appearances/protos/CementTiles.proto"
EXTERNPROTO "https://raw.githubusercontent.com/cyberbotics/webots/R2023b/projects/objects/floors/protos/CircleArena.proto"
EXTERNPROTO "https://raw.githubusercontent.com/cyberbotics/webots/R2023b/projects/appearances/protos/Parquetry.proto"
EXTERNPROTO "https://raw.githubusercontent.com/cyberbotics/webots/R2023b/projects/objects/toys/protos/RubberDuck.proto"

WorldInfo {
}
Viewpoint {
  orientation -0.24770661779650935 0.2625903367362494 0.9325705048695017 1.6733255791371697
  position 1.0622671921550122 -11.14284518033394 5.186016483056747
}
TexturedBackground {
}
TexturedBackgroundLight {
}
DEF Outer_Fi RectangleArena {
  floorSize 3 3
  floorTileSize 1 1
  floorAppearance Parquetry {
    type "dark strip"
    colorOverride 0 1 0
    IBLStrength 10
  }
  wallThickness 0.1
  wallHeight 0.5
}
RectangleArena {
  name "rectangle arena(1)"
  floorSize 0.156576 0.156576
  floorTileSize 1 1
  floorAppearance Parquetry {
    type "dark strip"
    colorOverride 0 1 0
    IBLStrength 10
  }
  wallThickness 0.001
  wallHeight 0.001
}
DEF RobotResource Robot {
  translation 3.778813149864163 1.077229037869003e-08 0.2244056746403672
  rotation -0.9999999953815698 3.977777330629997e-10 -9.610858622912322e-05 4.7848314236612e-08
  children [
    DEF CameraBaseTransform Transform {
      translation -0.01 0 0.2
      scale 1 1 2
      children [
        DEF CenterOfRotation_Horizontal Shape {
          appearance PBRAppearance {
            baseColor 1 0 0
            transparency 1
          }
          geometry Box {
            size 0.1 0.1 0.001
          }
        }
        DEF CenterOfRotation_Vertical Shape {
          appearance PBRAppearance {
            baseColor 1 0 0
            transparency 1
          }
          geometry Box {
            size 0.001 0.1 0.1
          }
        }
        DEF CameraBaseModel Shape {
          appearance PBRAppearance {
            baseColor 0.576471 0.576471 0.576471
            transparency 0.01
            metalness 0
          }
          geometry Box {
            size 0.1 0.1 0.1
          }
        }
      ]
    }
    DEF HingeCameraArm HingeJoint {
      jointParameters HingeJointParameters {
        axis 0 1 0
        anchor -0.011 0 0.25
      }
      device [
        DEF rm RotationalMotor {
          name "camera_motor_object"
          minPosition -10
          maxPosition 10
        }
      ]
      endPoint Solid {
        translation 0.19 0 0.25
        rotation 0 1 0 0
        children [
          Solid {
            translation -0.1 0 0
            children [
              Shape {
                geometry Box {
                  size 0.2 0.08 0.08
                }
              }
            ]
            name "solid(1)"
          }
          Solid {
            children [
              HingeJoint {
                jointParameters HingeJointParameters {
                  position 1.751040000000001
                }
                device [
                  DEF RM RotationalMotor {
                    name "camera_motor"
                  }
                ]
                endPoint Solid {
                  rotation 1 0 0 0
                  children [
                    DEF camera_camera Camera {
                    }
                  ]
                  name "camera_camera"
                }
              }
              Shape {
                appearance PBRAppearance {
                  baseColor 0 0.101961 0
                  metalness 0
                }
                geometry Box {
                  size 0.1 0.1 0.1
                }
              }
            ]
          }
        ]
      }
    }
    TouchSensor {
      translation 0.25 0.1 0
      rotation 0 0 1 0.261799
      children [
        DEF TouchSensor Shape {
          appearance CementTiles {
          }
          geometry Box {
            size 0.05 0.15 0.15
          }
        }
      ]
      name "left sensor"
      boundingObject USE TouchSensor
    }
    TouchSensor {
      translation 0.25 -0.1 0
      rotation 0 0 1 -0.261799
      children [
        DEF TouchSensor Shape {
          appearance CementTiles {
          }
          geometry Box {
            size 0.05 0.15 0.15
          }
        }
      ]
      name "right sensor"
      boundingObject USE TouchSensor
    }
    Track {
      translation 0 0.3 -0.125
      children [
        TrackWheel {
          position 0.175 0
          rotation 0.9733537139906535 0.162145543117136 -0.16214613873863984 1.5978044495345327
          children [
            Shape {
              geometry Box {
                size 0.1 0.1 0.1
              }
            }
            DEF Sandwhich_Wheel Shape {
              appearance PBRAppearance {
              }
              geometry Cylinder {
                height 0.05
                radius 0.1
              }
            }
          ]
        }
        TrackWheel {
          position -0.175 0
          rotation 0.9733537139906535 0.162145543117136 -0.16214613873863984 1.5978044495345327
          children [
            Shape {
              geometry Box {
                size 0.1 0.1 0.1
              }
            }
            DEF Sandwhich_Wheel Shape {
              appearance PBRAppearance {
              }
              geometry Cylinder {
                height 0.05
                radius 0.1
              }
            }
          ]
        }
      ]
      name "track1"
      boundingObject Group {
        children [
          Pose {
            translation 0.175 0 0
            rotation 1 0 0 1.5708
            children [
              Cylinder {
                height 0.1
                radius 0.1
              }
            ]
          }
          Pose {
            translation -0.175 0 0
            rotation 1 0 0 1.5708
            children [
              Cylinder {
                height 0.1
                radius 0.1
              }
            ]
          }
          DEF Track_Box_Shape Box {
            size 0.35 0.1 0.2
          }
        ]
      }
      physics Physics {
      }
      device [
        LinearMotor {
          name "leftMotor"
        }
      ]
      animatedGeometry Shape {
        appearance Appearance {
          material Material {
            diffuseColor 0 0 0
          }
        }
        geometry DEF Track_Box_Shape Box {
          size 0.05 0.1 0.01
        }
      }
      geometriesCount 25
    }
    Track {
      translation 0 -0.3 -0.125
      children [
        TrackWheel {
          position 0.175 0
          rotation 0.9469687502461381 -0.22721114273171455 0.22721197740395566 1.6252622358781206
          children [
            Shape {
              geometry Box {
                size 0.1 0.1 0.1
              }
            }
            DEF Sandwhich_Wheel Shape {
              appearance PBRAppearance {
              }
              geometry Cylinder {
                height 0.05
                radius 0.1
              }
            }
          ]
        }
        TrackWheel {
          position -0.175 0
          rotation 0.9469687502461381 -0.22721114273171455 0.22721197740395566 1.6252622358781206
          children [
            Shape {
              geometry Box {
                size 0.1 0.1 0.1
              }
            }
            DEF Sandwhich_Wheel Shape {
              appearance PBRAppearance {
              }
              geometry Cylinder {
                height 0.05
                radius 0.1
              }
            }
          ]
        }
      ]
      name "track2"
      boundingObject Group {
        children [
          Pose {
            translation 0.175 0 0
            rotation 1 0 0 1.5708
            children [
              Cylinder {
                height 0.1
                radius 0.1
              }
            ]
          }
          Pose {
            translation -0.175 0 0
            rotation 1 0 0 1.5708
            children [
              Cylinder {
                height 0.1
                radius 0.1
              }
            ]
          }
          DEF Track_Box_Shape Box {
            size 0.35 0.1 0.2
          }
        ]
      }
      physics Physics {
      }
      device [
        LinearMotor {
          name "rightMotor"
        }
      ]
      animatedGeometry Shape {
        appearance Appearance {
          material Material {
            diffuseColor 0 0 0
          }
        }
        geometry DEF Track_Box_Shape Box {
          size 0.05 0.1 0.01
        }
      }
      geometriesCount 25
    }
    DEF Plate Shape {
      appearance BrushedAluminium {
        colorOverride 1 0.5 0.4
      }
      geometry Box {
        size 0.5 0.5 0.35
      }
    }
  ]
  name "robot(1)"
  boundingObject USE Plate
  physics Physics {
    density -1
    mass 2
  }
  controller "Camera_Tester"
}
CircleArena {
  translation 0 0 0.001
  radius 0.156576
  floorAppearance Parquetry {
    type "dark strip"
    IBLStrength 1000
  }
  floorTileSize 1 1
  wallThickness 0.005
  wallHeight 0.0001
  wallAppearance BrushedAluminium {
    colorOverride 0 0 0
  }
}
RubberDuck {
  translation -2.224334249366509 -4.179711230559197e-13 0.0810113073301956
  rotation 9.838977514502343e-06 -7.971197826043455e-06 -0.9999999999198274 9.957841694344524e-13
  name "Evil duck"
  scale 4
  bodyColor 0.137255 0.439216 1
  immersionProperties []
}
Solid {
  translation 1.1 -1.8 0.17576498440448401
  rotation -0.9084892605082175 0.2018865023350296 0.3659086002216401 2.298459301144942e-17
  children [
    Shape {
      appearance Appearance {
        material Material {
          diffuseColor 0.666667 0 0
          emissiveColor 0.666667 0 0
          specularColor 1 1 1
        }
      }
      geometry Box {
        size 0.35 0.35 0.35
      }
    }
  ]
  name "Box"
  boundingObject Box {
    size 0.35 0.35 0.35
  }
  physics Physics {
    density -1
    mass 0.6
  }
}
Solid {
  translation 1.1 1.8 0.17576498440448401
  rotation -0.9084892605082175 0.2018865023350296 0.3659086002216401 2.298459301144942e-17
  children [
    Shape {
      appearance Appearance {
        material Material {
          diffuseColor 0.666667 0 0
          emissiveColor 0.666667 0 0
          specularColor 1 1 1
        }
      }
      geometry Box {
        size 0.35 0.35 0.35
      }
    }
  ]
  name "Box(1)"
  boundingObject Box {
    size 0.35 0.35 0.35
  }
  physics Physics {
    density -1
    mass 0.6
  }
}
Solid {
  translation 0.20149 3.12811e-08 0.175796
  children [
    Shape {
      appearance Appearance {
        material Material {
          diffuseColor 0.172549 0.34902 0.521569
          emissiveColor 0.172549 0.34902 0.521569
          specularColor 1 1 1
        }
      }
      geometry Sphere {
        radius 0.025
      }
    }
  ]
  name "Ball"
  boundingObject Sphere {
    radius 0.025
  }
  physics Physics {
    density -1
    mass 0.13
  }
}
Solid {
  translation -1.1 1.8 0.17579631983332394
  children [
    Shape {
      appearance Appearance {
        material Material {
          diffuseColor 0.172549 0.34902 0.521569
          emissiveColor 0.172549 0.34902 0.521569
          specularColor 1 1 1
        }
      }
      geometry Sphere {
        radius 0.175
      }
    }
  ]
  name "Ball(1)"
  boundingObject Sphere {
    radius 0.175
  }
  physics Physics {
    density -1
    mass 0.13
  }
}
Solid {
  translation -1.1 -1.8 0.17579631983332394
  children [
    Shape {
      appearance Appearance {
        material Material {
          diffuseColor 0.172549 0.34902 0.521569
          emissiveColor 0.172549 0.34902 0.521569
          specularColor 1 1 1
        }
      }
      geometry Sphere {
        radius 0.175
      }
    }
  ]
  name "Ball(2)"
  boundingObject Sphere {
    radius 0.175
  }
  physics Physics {
    density -1
    mass 0.13
  }
}
DEF ScaleRobot Robot {
  translation 0 0 0.12
  children [
    DEF TouchSensor_Right TouchSensor {
      name "touch sensor(1)"
    }
    DEF BaseShapes_Group Group {
      children [
        DEF BaseShape_Top_Transform Pose {
        }
        DEF ModuleShapes_Group Group {
        }
        DEF MotorShapes_Group Group {
        }
        DEF BaseShape_Floor_Root Shape {
          appearance PBRAppearance {
          }
          geometry Box {
            size 0.1143 0.0635 0.1016
          }
        }
      ]
    }
    DEF TouchSensor_Left TouchSensor {
    }
    DEF CameraArm_HingeJoint HingeJoint {
    }
    DEF CameraBase_Transfrom Pose {
    }
  ]
}
