#VRML_SIM R2023b utf8

EXTERNPROTO "https://raw.githubusercontent.com/cyberbotics/webots/R2023b/projects/objects/backgrounds/protos/TexturedBackground.proto"
EXTERNPROTO "https://raw.githubusercontent.com/cyberbotics/webots/R2023b/projects/objects/backgrounds/protos/TexturedBackgroundLight.proto"
EXTERNPROTO "https://raw.githubusercontent.com/cyberbotics/webots/R2023b/projects/objects/floors/protos/RectangleArena.proto"
EXTERNPROTO "https://raw.githubusercontent.com/cyberbotics/webots/R2023b/projects/appearances/protos/BrushedAluminium.proto"
EXTERNPROTO "https://raw.githubusercontent.com/cyberbotics/webots/R2023b/projects/appearances/protos/CementTiles.proto"
EXTERNPROTO "https://raw.githubusercontent.com/cyberbotics/webots/R2023b/projects/objects/floors/protos/CircleArena.proto"
EXTERNPROTO "https://raw.githubusercontent.com/cyberbotics/webots/R2023b/projects/appearances/protos/Parquetry.proto"
EXTERNPROTO "https://raw.githubusercontent.com/cyberbotics/webots/R2023b/projects/objects/toys/protos/RubberDuck.proto"

WorldInfo {
}
Viewpoint {
  orientation -0.0541777020850228 0.06938276398677416 0.9961178688580695 1.6900370403847111
  position 0.40205591693868836 -2.37503856036157 0.4988755404683831
}
TexturedBackground {
}
TexturedBackgroundLight {
}
RectangleArena {
  floorSize 10 10
  floorTileSize 1 1
  floorAppearance Parquetry {
    type "dark strip"
    colorOverride 0 1 0
    IBLStrength 10
  }
  wallThickness 0.1
  wallHeight 0.5
}
Robot {
  translation -7.066955694988428e-17 1.0559869602662494e-08 0.22409881952103677
  rotation -1 5.453821651709975e-10 -7.49590004612749e-10 4.693315582527811e-08
  children [
    HingeJoint {
      jointParameters HingeJointParameters {
        axis 0 1 0
        anchor 0 0 0.28
      }
      device [
        DEF rm RotationalMotor {
          name "rm"
          minPosition -2
        }
      ]
      endPoint Solid {
        translation 0.19 0 0.25
        rotation 0 1 0 0
        children [
          Solid {
            translation -0.1 0 0
            children [
              Shape {
                geometry Box {
                  size 0.2 0.08 0.08
                }
              }
            ]
            name "solid(1)"
          }
          Solid {
            children [
              HingeJoint {
                jointParameters HingeJointParameters {
                  position 1.751040000000001
                }
                device [
                  DEF RM RotationalMotor {
                    name "camera_motor"
                  }
                ]
                endPoint Solid {
                  rotation 1 0 0 1.7510400000000013
                  children [
                    DEF camera_camera Camera {
                    }
                  ]
                  name "camera_camera"
                }
              }
              Shape {
                appearance PBRAppearance {
                }
                geometry Box {
                  size 0.1 0.1 0.1
                }
              }
            ]
          }
        ]
      }
    }
    TouchSensor {
      translation 0.25 0.1 0
      rotation 0 0 1 0.261799
      children [
        DEF TouchSensor Shape {
          appearance CementTiles {
          }
          geometry Box {
            size 0.05 0.15 0.15
          }
        }
      ]
      name "left sensor"
      boundingObject USE TouchSensor
    }
    TouchSensor {
      translation 0.25 -0.1 0
      rotation 0 0 1 -0.261799
      children [
        DEF TouchSensor Shape {
          appearance CementTiles {
          }
          geometry Box {
            size 0.05 0.15 0.15
          }
        }
      ]
      name "right sensor"
      boundingObject USE TouchSensor
    }
    Track {
      translation 0 0.3 -0.125
      children [
        TrackWheel {
          position 0.175 0
          rotation 0.9733537139906535 0.162145543117136 -0.16214613873863984 1.5978044495345327
          children [
            Shape {
              geometry Box {
                size 0.1 0.1 0.1
              }
            }
            DEF Sandwhich_Wheel Shape {
              appearance PBRAppearance {
              }
              geometry Cylinder {
                height 0.05
                radius 0.1
              }
            }
          ]
        }
        TrackWheel {
          position -0.175 0
          rotation 0.9733537139906535 0.162145543117136 -0.16214613873863984 1.5978044495345327
          children [
            Shape {
              geometry Box {
                size 0.1 0.1 0.1
              }
            }
            DEF Sandwhich_Wheel Shape {
              appearance PBRAppearance {
              }
              geometry Cylinder {
                height 0.05
                radius 0.1
              }
            }
          ]
        }
      ]
      name "track1"
      boundingObject Group {
        children [
          Pose {
            translation 0.175 0 0
            rotation 1 0 0 1.5708
            children [
              Cylinder {
                height 0.1
                radius 0.1
              }
            ]
          }
          Pose {
            translation -0.175 0 0
            rotation 1 0 0 1.5708
            children [
              Cylinder {
                height 0.1
                radius 0.1
              }
            ]
          }
          DEF Track_Box_Shape Box {
            size 0.35 0.1 0.2
          }
        ]
      }
      physics Physics {
      }
      device [
        LinearMotor {
          name "leftMotor"
        }
      ]
      animatedGeometry Shape {
        appearance Appearance {
          material Material {
            diffuseColor 0 0 0
          }
        }
        geometry DEF Track_Box_Shape Box {
          size 0.05 0.1 0.01
        }
      }
      geometriesCount 25
    }
    Track {
      translation 0 -0.3 -0.125
      children [
        TrackWheel {
          position 0.175 0
          rotation 0.9469687502461381 -0.22721114273171455 0.22721197740395566 1.6252622358781206
          children [
            Shape {
              geometry Box {
                size 0.1 0.1 0.1
              }
            }
            DEF Sandwhich_Wheel Shape {
              appearance PBRAppearance {
              }
              geometry Cylinder {
                height 0.05
                radius 0.1
              }
            }
          ]
        }
        TrackWheel {
          position -0.175 0
          rotation 0.9469687502461381 -0.22721114273171455 0.22721197740395566 1.6252622358781206
          children [
            Shape {
              geometry Box {
                size 0.1 0.1 0.1
              }
            }
            DEF Sandwhich_Wheel Shape {
              appearance PBRAppearance {
              }
              geometry Cylinder {
                height 0.05
                radius 0.1
              }
            }
          ]
        }
      ]
      name "track2"
      boundingObject Group {
        children [
          Pose {
            translation 0.175 0 0
            rotation 1 0 0 1.5708
            children [
              Cylinder {
                height 0.1
                radius 0.1
              }
            ]
          }
          Pose {
            translation -0.175 0 0
            rotation 1 0 0 1.5708
            children [
              Cylinder {
                height 0.1
                radius 0.1
              }
            ]
          }
          DEF Track_Box_Shape Box {
            size 0.35 0.1 0.2
          }
        ]
      }
      physics Physics {
      }
      device [
        LinearMotor {
          name "rightMotor"
        }
      ]
      animatedGeometry Shape {
        appearance Appearance {
          material Material {
            diffuseColor 0 0 0
          }
        }
        geometry DEF Track_Box_Shape Box {
          size 0.05 0.1 0.01
        }
      }
      geometriesCount 25
    }
    DEF Plate Shape {
      appearance BrushedAluminium {
        colorOverride 1 0.5 0.4
      }
      geometry Box {
        size 0.5 0.5 0.35
      }
    }
  ]
  boundingObject USE Plate
  physics Physics {
    density -1
    mass 2
  }
  controller "Camera_Tester"
}
CircleArena {
  translation 0 0 0.001
  radius 3
  floorAppearance Parquetry {
    type "dark strip"
    IBLStrength 1000
  }
  floorTileSize 1 1
  wallThickness 0.25
  wallHeight 0.01
  wallAppearance BrushedAluminium {
    colorOverride 0 0 0
  }
}
RubberDuck {
  translation -2.2000349966342423 -7.274133527480676e-13 0.0806132660445559
  rotation -8.547091094424679e-08 -0.9999999999887605 4.740441445039966e-06 5.082910646985563e-07
  name "Evil duck"
  scale 4
  bodyColor 0.137255 0.439216 1
  immersionProperties []
}
Solid {
  translation 1.1 -1.8 0.17576455999999993
  rotation -0.8160420852717016 -6.943249979678113e-15 0.5779924870319795 2.2745293040288138e-17
  children [
    Shape {
      appearance Appearance {
        material Material {
          diffuseColor 0.666667 0 0
          emissiveColor 0.666667 0 0
          specularColor 1 1 1
        }
      }
      geometry Box {
        size 0.35 0.35 0.35
      }
    }
  ]
  name "Box"
  boundingObject Box {
    size 0.35 0.35 0.35
  }
  physics Physics {
    density -1
    mass 0.6
  }
}
Solid {
  translation 1.1 1.8 0.17576455999999993
  rotation -0.8160420852717016 -6.943249979678113e-15 0.5779924870319795 2.2745293040288138e-17
  children [
    Shape {
      appearance Appearance {
        material Material {
          diffuseColor 0.666667 0 0
          emissiveColor 0.666667 0 0
          specularColor 1 1 1
        }
      }
      geometry Box {
        size 0.35 0.35 0.35
      }
    }
  ]
  name "Box(1)"
  boundingObject Box {
    size 0.35 0.35 0.35
  }
  physics Physics {
    density -1
    mass 0.6
  }
}
Solid {
  translation 2.2 0 0.17579595199999995
  children [
    Shape {
      appearance Appearance {
        material Material {
          diffuseColor 0.172549 0.34902 0.521569
          emissiveColor 0.172549 0.34902 0.521569
          specularColor 1 1 1
        }
      }
      geometry Sphere {
        radius 0.175
      }
    }
  ]
  name "Ball"
  boundingObject Sphere {
    radius 0.175
  }
  physics Physics {
    density -1
    mass 0.13
  }
}
Solid {
  translation -1.1 1.8 0.17579595199999995
  children [
    Shape {
      appearance Appearance {
        material Material {
          diffuseColor 0.172549 0.34902 0.521569
          emissiveColor 0.172549 0.34902 0.521569
          specularColor 1 1 1
        }
      }
      geometry Sphere {
        radius 0.175
      }
    }
  ]
  name "Ball(1)"
  boundingObject Sphere {
    radius 0.175
  }
  physics Physics {
    density -1
    mass 0.13
  }
}
Solid {
  translation -1.1 -1.8 0.17579595199999995
  children [
    Shape {
      appearance Appearance {
        material Material {
          diffuseColor 0.172549 0.34902 0.521569
          emissiveColor 0.172549 0.34902 0.521569
          specularColor 1 1 1
        }
      }
      geometry Sphere {
        radius 0.175
      }
    }
  ]
  name "Ball(2)"
  boundingObject Sphere {
    radius 0.175
  }
  physics Physics {
    density -1
    mass 0.13
  }
}
