#VRML_SIM R2023b utf8

EXTERNPROTO "https://raw.githubusercontent.com/cyberbotics/webots/R2023b/projects/objects/backgrounds/protos/TexturedBackground.proto"
EXTERNPROTO "https://raw.githubusercontent.com/cyberbotics/webots/R2023b/projects/objects/backgrounds/protos/TexturedBackgroundLight.proto"
EXTERNPROTO "https://raw.githubusercontent.com/cyberbotics/webots/R2023b/projects/objects/floors/protos/RectangleArena.proto"
EXTERNPROTO "https://raw.githubusercontent.com/cyberbotics/webots/R2023b/projects/appearances/protos/BrushedAluminium.proto"
EXTERNPROTO "https://raw.githubusercontent.com/cyberbotics/webots/R2023b/projects/appearances/protos/CementTiles.proto"
EXTERNPROTO "https://raw.githubusercontent.com/cyberbotics/webots/R2023b/projects/appearances/protos/BakelitePlastic.proto"
EXTERNPROTO "https://raw.githubusercontent.com/cyberbotics/webots/R2023b/projects/objects/floors/protos/CircleArena.proto"
EXTERNPROTO "https://raw.githubusercontent.com/cyberbotics/webots/R2023b/projects/appearances/protos/Parquetry.proto"

WorldInfo {
}
Viewpoint {
  orientation -0.4020956983421037 -0.13594220679746488 0.9054494827354045 3.794830779013997
  position 5.3878214924658465 5.075466227436585 8.090842877126608
}
TexturedBackground {
}
TexturedBackgroundLight {
}
RectangleArena {
  floorSize 10 10
  floorTileSize 1 1
  floorAppearance Parquetry {
    type "dark strip"
    colorOverride 0 1 0
    IBLStrength 10
  }
  wallThickness 0.1
  wallHeight 0.5
}
Robot {
  translation 0 0 0.4
  children [
    Solid {
      translation 0 0 0.2
      children [
        HingeJoint {
          jointParameters HingeJointParameters {
            position 1.57
            axis 0 1 0
            anchor 0 0 0.05
          }
          device [
            RotationalMotor {
              name "camera motor"
              maxPosition 1.75
            }
          ]
          endPoint Solid {
            translation 0.09998747870966607 -6.170639877511876e-06 0.049951635625651754
            rotation 8.061402666508011e-06 0.9999999997400977 -2.1326473543421014e-05 1.5700000003756482
            children [
              Camera {
                translation -7.13725e-07 0 0.16
                rotation 0 1 0 -1.5707953071795862
              }
              DEF CameraMount Shape {
                appearance BakelitePlastic {
                }
                geometry Box {
                  size 0.05 0.1 0.3
                }
              }
            ]
            boundingObject USE CameraMount
            physics Physics {
            }
          }
        }
        Shape {
          appearance BakelitePlastic {
          }
          geometry Box {
            size 0.05 0.1 0.1
          }
        }
      ]
      name "Camera Joint"
      boundingObject Box {
        size 0.05 0.1 0.025
      }
      physics Physics {
      }
    }
    TouchSensor {
      translation 0.25 0.1 0
      rotation 0 0 1 0.261799
      children [
        DEF TouchSensor Shape {
          appearance CementTiles {
          }
          geometry Box {
            size 0.05 0.15 0.15
          }
        }
      ]
      name "left sensor"
      boundingObject USE TouchSensor
    }
    TouchSensor {
      translation 0.25 -0.1 0
      rotation 0 0 1 -0.261799
      children [
        DEF TouchSensor Shape {
          appearance CementTiles {
          }
          geometry Box {
            size 0.05 0.15 0.15
          }
        }
      ]
      name "right sensor"
      boundingObject USE TouchSensor
    }
    Track {
      translation 0 0.3 -0.125
      children [
        TrackWheel {
          position 0.175 0
          rotation 0.08354071641558707 0.7046336995578861 -0.7046362878451102 2.974898900620828
          children [
            Shape {
              geometry Box {
                size 0.1 0.1 0.1
              }
            }
            DEF Sandwhich_Wheel Shape {
              appearance PBRAppearance {
              }
              geometry Cylinder {
                height 0.05
                radius 0.1
              }
            }
          ]
        }
        TrackWheel {
          position -0.175 0
          rotation 0.08354071641558707 0.7046336995578861 -0.7046362878451102 2.974898900620828
          children [
            Shape {
              geometry Box {
                size 0.1 0.1 0.1
              }
            }
            DEF Sandwhich_Wheel Shape {
              appearance PBRAppearance {
              }
              geometry Cylinder {
                height 0.05
                radius 0.1
              }
            }
          ]
        }
      ]
      name "track1"
      boundingObject Group {
        children [
          Pose {
            translation 0.175 0 0
            rotation 1 0 0 1.5708
            children [
              Cylinder {
                height 0.1
                radius 0.1
              }
            ]
          }
          Pose {
            translation -0.175 0 0
            rotation 1 0 0 1.5708
            children [
              Cylinder {
                height 0.1
                radius 0.1
              }
            ]
          }
          DEF Track_Box_Shape Box {
            size 0.35 0.1 0.2
          }
        ]
      }
      physics Physics {
      }
      device [
        LinearMotor {
          name "leftMotor"
        }
      ]
      animatedGeometry Shape {
        appearance Appearance {
          material Material {
            diffuseColor 0 0 0
          }
        }
        geometry DEF Track_Box_Shape Box {
          size 0.05 0.1 0.01
        }
      }
      geometriesCount 25
    }
    Track {
      translation 0 -0.3 -0.125
      children [
        TrackWheel {
          position 0.175 0
          rotation 0.12092161550172097 0.7019167840239385 -0.7019193623272874 2.900918810518909
          children [
            Shape {
              geometry Box {
                size 0.1 0.1 0.1
              }
            }
            DEF Sandwhich_Wheel Shape {
              appearance PBRAppearance {
              }
              geometry Cylinder {
                height 0.05
                radius 0.1
              }
            }
          ]
        }
        TrackWheel {
          position -0.175 0
          rotation 0.12092161550172097 0.7019167840239385 -0.7019193623272874 2.900918810518909
          children [
            Shape {
              geometry Box {
                size 0.1 0.1 0.1
              }
            }
            DEF Sandwhich_Wheel Shape {
              appearance PBRAppearance {
              }
              geometry Cylinder {
                height 0.05
                radius 0.1
              }
            }
          ]
        }
      ]
      name "track2"
      boundingObject Group {
        children [
          Pose {
            translation 0.175 0 0
            rotation 1 0 0 1.5708
            children [
              Cylinder {
                height 0.1
                radius 0.1
              }
            ]
          }
          Pose {
            translation -0.175 0 0
            rotation 1 0 0 1.5708
            children [
              Cylinder {
                height 0.1
                radius 0.1
              }
            ]
          }
          DEF Track_Box_Shape Box {
            size 0.35 0.1 0.2
          }
        ]
      }
      physics Physics {
      }
      device [
        LinearMotor {
          name "rightMotor"
        }
      ]
      animatedGeometry Shape {
        appearance Appearance {
          material Material {
            diffuseColor 0 0 0
          }
        }
        geometry DEF Track_Box_Shape Box {
          size 0.05 0.1 0.01
        }
      }
      geometriesCount 25
    }
    DEF Plate Shape {
      appearance BrushedAluminium {
        colorOverride 1 0.5 0.4
      }
      geometry Box {
        size 0.5 0.5 0.35
      }
    }
  ]
  boundingObject USE Plate
  physics Physics {
  }
  controller "FirstChallengeController"
}
CircleArena {
  translation 0 0 0.1
  radius 2.5
  floorAppearance Parquetry {
    type "dark strip"
    IBLStrength 1000
  }
  floorTileSize 1 1
  wallThickness 0.25
  wallHeight 0.001
  wallAppearance BrushedAluminium {
    colorOverride 0 0 0
  }
}
